Workbook

Sheet Read Me
A1: Relivable (working title) - Feature Matrix
A2: Date | B2: 2026-10-26
A3: Status | B3: Phase 1 planning draft for client review. Estimates, not quotes or forecasts.
A4: Purpose | B4: One client-ready view of every Relivable feature against BitLife, with priority, effort, access (free vs paid) and source, plus the store catalogue, budget, roadmap and KPIs from the Phase 1 vault.
A5: Sources | B5: docs/phase-1: _Concept Brief; 04 App Breakdown - Core Life Systems; 04 App Breakdown - Social, Meta and Premium; 06 Monetization and Economy; 11 Roadmap Team and Budget; 12 Risks and KPIs.
A7: Sheets
A8: Feature Matrix | B8: One row per feature or sub-feature across all 10 Core modules and 14 Social/Meta/Premium modules. Filters, frozen header, dropdowns and colour coding.
A9: Summary | B9: Live COUNTIFS: Module x Priority, Status, Access x Priority, and the fair-forever check (no career/core-system row is Plus or Pack).
A10: Store Catalogue | B10: Products, prices, contents and type from note 06, plus rewarded-ad placements and price checks.
A11: Budget | B11: Per-phase line items (Low / High / US reference) with SUM totals and the cumulative total to launch; LiveOps monthly run rate.
A12: Roadmap | B12: Phases, dates, gates, deliverables, exit criteria, Gantt tasks and team FTE per role.
A13: KPIs | B13: KPI, definition, target, benchmark and source for North Star, acquisition, engagement, retention, monetisation and quality.
A15: Feature Matrix columns
A16: ID | B16: MODULE-SUB-NNN. CORE-xx = Core Life Systems note; SOC-xx = Social, Meta and Premium note. Codes: CC character creation, ST stats/traits, CL core loop/storylets, ED education, CA careers, MO money/business, AS assets/home, CR crime/justice, HE health/death, WO countries/world; RE relationships, LO love/marriage, CH children, GE generations/dynasty, FA fame, PE pets, AC Activities hub, ID identity, AR achievements/Titles/Recap, CE challenges/events, AS async social/Creator Mode, PR premium/editor, AI AI Storyteller, SE settings/accessibility/safety.
A17: Module | B17: Module name as in the 04 notes (dropdown list = Summary!A6:A29).
A18: Feature | B18: Feature or sub-feature name.
A19: Description | B19: Short description of the Relivable design.
A20: BitLife equivalent | B20: What BitLife does today as last documented in research; 'Not documented' = no source found; 'None' = no equivalent (monetisation or add-on rows).
A21: Status vs BitLife | B21: Parity = matches BitLife's documented feature (redesigned UI). Improved = same idea, meaningfully better (free where BitLife charges, clearer, deeper). New = not documented in BitLife.
A22: Player value (1-5) | B22: Analyst estimate of player-facing value: 1 = minor polish, 2 = nice to have, 3 = solid feature, 4 = major draw, 5 = pillar-defining. Not from player data.
A23: Effort | B23: Analyst T-shirt estimate of build + content effort: S = under 1 week, M = 1-3 weeks, L = 1-2 months, XL = 2+ months or cross-cutting. To be re-estimated after the Phase 2 prototype.
A24: Priority | B24: Proto = Phase 2 vertical slice (birth to 30, ~150 events). MVP = Phase 3 soft launch (full life cycle, 1,500+ events). Launch = Phase 4 global launch (parity + 'better', 5 languages). LiveOps = Phase 5, after launch. Proto items are also in MVP.
A25: Access | B25: Free = base game for everyone. Plus = one-time Relivable Plus (~$9.99) or the No Ads / Plus Upgrade path. Pack = one-off paid content: Story Packs ($2.99-3.99), cosmetic sets, Welcome Pack, bundles. Season = optional Season Pass ($4.99). Ad = optional, capped rewarded ad (rewarded-only, max 4 per session and 8 per day).
A26: Dependencies | B26: Other modules (by code) or documents the feature relies on.
A27: Source note | B27: Note and section the row comes from. '(priority inferred)' = the note describes the feature but its priority table does not list it, so the priority was assigned by the analyst from context.
A28: Career / core system? | B28: Added audit column (a fair-forever check). Yes = the row is a career, a core life system, or an always-free player protection (accessibility, identity, restore). Under pillar 3 every Yes row must be Free; the Summary check counts violations. No = add-ons such as editor tools, Rewind, cosmetics, storylines, ad boosts and generations 5-8.
A30: Colour coding
A31: Priority colours | B31: Proto = lavender, MVP = green, Launch = blue, LiveOps = peach.
A32: Access colours | B32: Free = green, Plus = gold, Pack = salmon, Season = blue, Ad = grey. A red 'Career / core system?' cell means a Yes row is Plus or Pack (a pillar-3 violation).
A33: Other sheets | B33: Blue text = hardcoded input copied from a source note; black text = formula.
A35: Resolved decisions applied
A36: Search bar | B36: Search / command bar sits at the bottom of the hub (thumb zone).
A37: Life Titles | B37: End-of-life awards are called 'Life Titles' (replace BitLife ribbons).
A38: Sparks | B38: One earn-only soft currency, 'Sparks'; never sold, no premium currency.
A39: Ads | B39: Rewarded-only, opt-in, capped at 4 per session and 8 per day (90 s cooldown).
A40: Generations | B40: Every dynasty is capped at 8 generations. Free = founder + 3 heirs (Generation 4); Plus extends to Generation 8. At the cap the dynasty is completed and saved; new dynasties are unlimited.
A41: Rewind | B41: 1 free per life + 1 per day via rewarded ad; unlimited in Plus; never sold per use.
A42: Fair forever | B42: All careers and core systems are free. Packs and seasons add storylines and cosmetics only.
A44: Evidence caveat
A45: BitLife facts | B45: Built from search-result snippets of fan guides and vendor pages (page fetching and Reddit were blocked). Treat them as last-documented behaviour, not the live 2026 build.
...

Sheet Feature Matrix
A1: ID | B1: Module | C1: Feature | D1: Description | E1: BitLife equivalent | F1: Status vs BitLife | G1: Player value (1-5) | H1: Effort | I1: Priority | J1: Access | K1: Dependencies | L1: Source note | M1: Career / core system?
A2: CORE-CC-001 | B2: Character creation | C2: "Surprise me" random life | D2: One-tap fully random life from the three-door New Life sheet | E2: Random new life | F2: Parity | G2: 5 | H2: S | I2: Proto | J2: Free | K2: CORE-ST, CORE-WO | L2: 04 Core, Module 1 (Priority and access table) | M2: Yes
A3: CORE-CC-002 | B3: Character creation | C3: Custom life builder (name, gender, country, city) | D3: Progressive stepper (Identity, Place and time, Family, Traits, Review) with a re-roll dice per step | E3: Custom People builder | F3: Improved | G3: 4 | H3: M | I3: Proto | J3: Free | K3: CORE-ST, CORE-WO | L3: 04 Core, Module 1 (Priority and access table) | M3: Yes
A4: CORE-CC-003 | B4: Character creation | C4: Live preview card and life forecast | D4: Baby avatar, family summary and one-line forecast update as choices change | E4: None documented | F4: New | G4: 3 | H4: S | I4: MVP | J4: Free | K4: SOC-ID avatar | L4: 04 Core, Module 1 (redesign; priority inferred) | M4: Yes
A5: CORE-CC-004 | B5: Character creation | C5: Family setup presets | D5: Wealthy, modest, struggling, single parent, two mums, two dads, grandparents, foster care, adopted at birth | E5: Random chance of same-sex parents | F5: Improved | G5: 4 | H5: M | I5: MVP | J5: Free | K5: SOC-LO, SOC-CH | L5: 04 Core, Module 1 (Priority and access table) | M5: Yes
A6: CORE-CC-005 | B6: Character creation | C6: Twins and triplets at creation | D6: Toggle to start life as a twin or triplet with siblings set up | E6: None documented (player request) | F6: New | G6: 4 | H6: M | I6: MVP | J6: Free | K6: SOC-CH | L6: 04 Core, Module 1 (Social note lists player twins at Launch; Core table used) | M6: Yes
A7: CORE-CC-006 | B7: Character creation | C7: Starting traits and flaw | D7: 2 starting traits + 1 flaw, picked or rolled, optional hidden trait revealed later | E7: None documented | F7: New | G7: 4 | H7: S | I7: MVP | J7: Free | K7: CORE-ST | L7: 04 Core, Module 1 (Priority and access table) | M7: Yes
A8: CORE-CC-007 | B8: Character creation | C8: Talent hint | D8: Optional talent (music, sport, art, maths, languages) raises one hidden stat cap by 15 | E8: None documented | F8: New | G8: 2 | H8: S | I8: MVP | J8: Free | K8: CORE-ST | L8: 04 Core, Module 1 (priority inferred) | M8: Yes
A9: CORE-CC-008 | B9: Character creation | C9: Seed codes (generate, enter, share, QR) | D9: Human-readable EL- seed on Review, death screen and recap; reproduces the start | E9: None documented | F9: New | G9: 4 | H9: M | I9: MVP | J9: Free | K9: CORE-CL, SOC-CE | L9: 04 Core, Module 1 (Priority and access table) | M9: Yes
A10: CORE-CC-009 | B10: Character creation | C10: Daily Seed | D10: One curated seed per day for everyone | E10: None documented | F10: New | G10: 3 | H10: S | I10: MVP | J10: Free | K10: SOC-CE | L10: 04 Core, Module 1 (Priority and access table) | M10: Yes
A11: CORE-CC-010 | B11: Character creation | C11: Difficulty presets and Ironman | D11: Gentle, Standard, Harsh; Ironman toggle disables Rewind and earns a badge | E11: None documented | F11: New | G11: 3 | H11: S | I11: MVP | J11: Free | K11: CORE-CL | L11: 04 Core, Module 1 (priority inferred) | M11: Yes
A12: CORE-CC-011 | B12: Character creation | C12: Era mode start year | D12: Choose a start year 1900-2040 in decade steps; era gates tech, jobs and laws | E12: None documented | F12: New | G12: 4 | H12: L | I12: Launch | J12: Free | K12: CORE-WO | L12: 04 Core, Module 1 (Priority and access table) | M12: Yes
A13: CORE-CC-012 | B13: Character creation | C13: Cast library (20 slots) | D13: Save custom people and place them as parents, siblings or NPCs in any life | E13: Saved custom characters | F13: Improved | G13: 3 | H13: M | I13: MVP | J13: Free | K13: SOC-RE | L13: 04 Core, Module 1 (Priority and access table) | M13: Yes
... A461: SOC-SE-019 | B461: Settings, accessibility and safety | C461: Support resources page | D461: Region-appropriate helplines linked from heavy storylines | E461: Not documented | F461: New | G461: 4 | H461: S | I461: Launch | J461: Free | K461: CORE-HE | L461: 04 Social, Section 14 (Priority and access table) | M461: Yes

Sheet Summary
A1: Summary: live counts from the Feature Matrix
A2: All numbers are COUNTIFS/SUM formulas over 'Feature Matrix' rows 2-1000, so they update when rows are added or edited.
A4: 1. Features by Module x Priority
A5: Module | B5: Proto | C5: MVP | D5: Launch | E5: LiveOps | F5: Total | G5: Avg player value | H5: Free | I5: Paid (Plus/Pack/Season) | J5: Ad
A6: Character creation | B6: =COUNTIFS('Feature Matrix'!$B$2:$B$1000,$A6,'Feature Matrix'!$I$2:$I$1000,B$5) -> 2 | C6: =COUNTIFS('Feature Matrix'!$B$2:$B$1000,$A6,'Feature Matrix'!$I$2:$I$1000,C$5) -> 11 | D6: =COUNTIFS('Feature Matrix'!$B$2:$B$1000,$A6,'Feature Matrix'!$I$2:$I$1000,D$5) -> 2 | E6: =COUNTIFS('Feature Matrix'!$B$2:$B$1000,$A6,'Feature Matrix'!$I$2:$I$1000,E$5) -> 2 | F6: =SUM(B6:E6) -> 17 | G6: =IFERROR(AVERAGEIFS('Feature Matrix'!$G$2:$G$1000,'Feature Matrix'!$B$2:$B$1000,$A6),0) -> 3.2941176 | H6: =COUNTIFS('Feature Matrix'!$B$2:$B$1000,$A6,'Feature Matrix'!$J$2:$J$1000,"Free") -> 14 | I6: =COUNTIFS('Feature Matrix'!$B$2:$B$1000,$A6,'Feature Matrix'!$J$2:$J$1000,"Plus")+COUNTIFS('Feature Matrix'!$B$2:$B$1000,$A6,'Feature Matrix'!$J$2:$J$1000,"Pack")+COUNTIFS('Feature Matrix'!$B$2:$B$1000,$A6,'Feature Matrix'!$J$2:$J$1000,"Season") -> 3 | J6: =COUNTIFS('Feature Matrix'!$B$2:$B$1000,$A6,'Feature Matrix'!$J$2:$J$1000,"Ad") -> 0
A7: Stats and traits | B7: =COUNTIFS('Feature Matrix'!$B$2:$B$1000,$A7,'Feature Matrix'!$I$2:$I$1000,B$5) -> 3 | C7: =COUNTIFS('Feature Matrix'!$B$2:$B$1000,$A7,'Feature Matrix'!$I$2:$I$1000,C$5) -> 6 | D7: =COUNTIFS('Feature Matrix'!$B$2:$B$1000,$A7,'Feature Matrix'!$I$2:$I$1000,D$5) -> 2 | E7: =COUNTIFS('Feature Matrix'!$B$2:$B$1000,$A7,'Feature Matrix'!$I$2:$I$1000,E$5) -> 0 | F7: =SUM(B7:E7) -> 11 | G7: =IFERROR(AVERAGEIFS('Feature Matrix'!$G$2:$G$1000,'Feature Matrix'!$B$2:$B$1000,$A7),0) -> 3.4545455 | H7: =COUNTIFS('Feature Matrix'!$B$2:$B$1000,$A7,'Feature Matrix'!$J$2:$J$1000,"Free") -> 10 | I7: =COUNTIFS('Feature Matrix'!$B$2:$B$1000,$A7,'Feature Matrix'!$J$2:$J$1000,"Plus")+COUNTIFS('Feature Matrix'!$B$2:$B$1000,$A7,'Feature Matrix'!$J$2:$J$1000,"Pack")+COUNTIFS('Feature Matrix'!$B$2:$B$1000,$A7,'Feature Matrix'!$J$2:$J$1000,"Season") -> 1 | J7: =COUNTIFS('Feature Matrix'!$B$2:$B$1000,$A7,'Feature Matrix'!$J$2:$J$1000,"Ad") -> 0
A8: Core loop and storylet engine | B8: =COUNTIFS('Feature Matrix'!$B$2:$B$1000,$A8,'Feature Matrix'!$I$2:$I$1000,B$5) -> 10 | C8: =COUNTIFS('Feature Matrix'!$B$2:$B$1000,$A8,'Feature Matrix'!$I$2:$I$1000,C$5) -> 11 | D8: =COUNTIFS('Feature Matrix'!$B$2:$B$1000,$A8,'Feature Matrix'!$I$2:$I$1000,D$5) -> 2 | E8: =COUNTIFS('Feature Matrix'!$B$2:$B$1000,$A8,'Feature Matrix'!$I$2:$I$1000,E$5) -> 0 | F8: =SUM(B8:E8) -> 23 | G8: =IFERROR(AVERAGEIFS('Feature Matrix'!$G$2:$G$1000,'Feature Matrix'!$B$2:$B$1000,$A8),0) -> 3.9565217 | H8: =COUNTIFS('Feature Matrix'!$B$2:$B$1000,$A8,'Feature Matrix'!$J$2:$J$1000,"Free") -> 21 | I8: =COUNTIFS('Feature Matrix'!$B$2:$B$1000,$A8,'Feature Matrix'!$J$2:$J$1000,"Plus")+COUNTIFS('Feature Matrix'!$B$2:$B$1000,$A8,'Feature Matrix'!$J$2:$J$1000,"Pack")+COUNTIFS('Feature Matrix'!$B$2:$B$1000,$A8,'Feature Matrix'!$J$2:$J$1000,"Season") -> 1 | J8: =COUNTIFS('Feature Matrix'!$B$2:$B$1000,$A8,'Feature Matrix'!$J$2:$J$1000,"Ad") -> 1
A9: Childhood and education | B9: =COUNTIFS('Feature Matrix'!$B$2:$B$1000,$A9,'Feature Matrix'!$I$2:$I$1000,B$5) -> 8 | C9: =COUNTIFS('Feature Matrix'!$B$2:$B$1000,$A9,'Feature Matrix'!$I$2:$I$1000,C$5) -> 15 | D9: =COUNTIFS('Feature Matrix'!$B$2:$B$1000,$A9,'Feature Matrix'!$I$2:$I$1000,D$5) -> 5 | E9: =COUNTIFS('Feature Matrix'!$B$2:$B$1000,$A9,'Feature Matrix'!$I$2:$I$1000,E$5) -> 1 | F9: =SUM(B9:E9) -> 29 | G9: =IFERROR(AVERAGEIFS('Feature Matrix'!$G$2:$G$1000,'Feature Matrix'!$B$2:$B$1000,$A9),0) -> 3.3103448 | H9: =COUNTIFS('Feature Matrix'!$B$2:$B$1000,$A9,'Feature Matrix'!$J$2:$J$1000,"Free") -> 28 | I9: =COUNTIFS('Feature Matrix'!$B$2:$B$1000,$A9,'Feature Matrix'!$J$2:$J$1000,"Plus")+COUNTIFS('Feature Matrix'!$B$2:$B$1000,$A9,'Feature Matrix'!$J$2:$J$1000,"Pack")+COUNTIFS('Feature Matrix'!$B$2:$B$1000,$A9,'Feature Matrix'!$J$2:$J$1000,"Season") -> 1 | J9: =COUNTIFS('Feature Matrix'!$B$2:$B$1000,$A9,'Feature Matrix'!$J$2:$J$1000,"Ad") -> 0
A10: Careers and jobs | B10: =COUNTIFS('Feature Matrix'!$B$2:$B$1000,$A10,'Feature Matrix'!$I$2:$I$1000,B$5) -> 5 | C10: =COUNTIFS('Feature Matrix'!$B$2:$B$1000,$A10,'Feature Matrix'!$I$2:$I$1000,C$5) -> 23 | D10: =COUNTIFS('Feature Matrix'!$B$2:$B$1000,$A10,'Feature Matrix'!$I$2:$I$1000,D$5) -> 18 | E10: =COUNTIFS('Feature Matrix'!$B$2:$B$1000,$A10,'Feature Matrix'!$I$2:$I$1000,E$5) -> 1 | F10: =SUM(B10:E10) -> 47 | G10: =IFERROR(AVERAGEIFS('Feature Matrix'!$G$2:$G$1000,'Feature Matrix'!$B$2:$B$1000,$A10),0) -> 3.2765957 | H10: =COUNTIFS('Feature Matrix'!$B$2:$B$1000,$A10,'Feature Matrix'!$J$2:$J$1000,"Free") -> 46 | I10: =COUNTIFS('Feature Matrix'!$B$2:$B$1000,$A10,'Feature Matrix'!$J$2:$J$1000,"Plus")+COUNTIFS('Feature Matrix'!$B$2:$B$1000,$A10,'Feature Matrix'!$J$2:$J$1000,"Pack")+COUNTIFS('Feature Matrix'!$B$2:$B$1000,$A10,'Feature Matrix'!$J$2:$J$1000,"Season") -> 1 | J10: =COUNTIFS('Feature Matrix'!$B$2:$B$1000,$A10,'Feature Matrix'!$J$2:$J$1000,"Ad") -> 0
A11: Money, business and investing | B11: =COUNTIFS('Feature Matrix'!$B$2:$B$1000,$A11,'Feature Matrix'!$I$2:$I$1000,B$5) -> 3 | C11: =COUNTIFS('Feature Matrix'!$B$2:$B$1000,$A11,'Feature Matrix'!$I$2:$I$1000,C$5) -> 14 | D11: =COUNTIFS('Feature Matrix'!$B$2:$B$1000,$A11,'Feature Matrix'!$I$2:$I$1000,D$5) -> 10 | E11: =COUNTIFS('Feature Matrix'!$B$2:$B$1000,$A11,'Feature Matrix'!$I$2:$I$1000,E$5) -> 1 | F11: =SUM(B11:E11) -> 28 | G11: =IFERROR(AVERAGEIFS('Feature Matrix'!$G$2:$G$1000,'Feature Matrix'!$B$2:$B$1000,$A11),0) -> 3.25 | H11: =COUNTIFS('Feature Matrix'!$B$2:$B$1000,$A11,'Feature Matrix'!$J$2:$J$1000,"Free") -> 26 | I11: =COUNTIFS('Feature Matrix'!$B$2:$B$1000,$A11,'Feature Matrix'!$J$2:$J$1000,"Plus")+COUNTIFS('Feature Matrix'!$B$2:$B$1000,$A11,'Feature Matrix'!$J$2:$J$1000,"Pack")+COUNTIFS('Feature Matrix'!$B$2:$B$1000,$A11,'Feature Matrix'!$J$2:$J$1000,"Season") -> 1 | J11: =COUNTIFS('Feature Matrix'!$B$2:$B$1000,$A11,'Feature Matrix'!$J$2:$J$1000,"Ad") -> 1
A12: Assets and home | B12: =COUNTIFS('Feature Matrix'!$B$2:$B$1000,$A12,'Feature Matrix'!$I$2:$I$1000,B$5) -> 0 | C12: =COUNTIFS('Feature Matrix'!$B$2:$B$1000,$A12,'Feature Matrix'!$I$2:$I$1000,C$5) -> 10 | D12: =COUNTIFS('Feature Matrix'!$B$2:$B$1000,$A12,'Feature Matrix'!$I$2:$I$1000,D$5) -> 12 | E12: =COUNTIFS('Feature Matrix'!$B$2:$B$1000,$A12,'Feature Matrix'!$I$2:$I$1000,E$5) -> 0 | F12: =SUM(B12:E12) -> 22 | G12: =IFERROR(AVERAGEIFS('Feature Matrix'!$G$2:$G$1000,'Feature Matrix'!$B$2:$B$1000,$A12),0) -> 3.2272727 | H12: =COUNTIFS('Feature Matrix'!$B$2:$B$1000,$A12,'Feature Matrix'!$J$2:$J$1000,"Free") -> 21 | I12: =COUNTIFS('Feature Matrix'!$B$2:$B$1000,$A12,'Feature Matrix'!$J$2:$J$1000,"Plus")+COUNTIFS('Feature Matrix'!$B$2:$B$1000,$A12,'Feature Matrix'!$J$2:$J$1000,"Pack")+COUNTIFS('Feature Matrix'!$B$2:$B$1000,$A12,'Feature Matrix'!$J$2:$J$1000,"Season") -> 1 | J12: =COUNTIFS('Feature Matrix'!$B$2:$B$1000,$A12,'Feature Matrix'!$J$2:$J$1000,"Ad") -> 0
A13: Crime, justice and prison | B13: =COUNTIFS('Feature Matrix'!$B$2:$B$1000,$A13,'Feature Matrix'!$I$2:$I$1000,B$5) -> 0 | C13: =COUNTIFS('Feature Matrix'!$B$2:$B$1000,$A13,'Feature Matrix'!$I$2:$I$1000,C$5) -> 13 | D13: =COUNTIFS('Feature Matrix'!$B$2:$B$1000,$A13,'Feature Matrix'!$I$2:$I$1000,D$5) -> 11 | E13: =COUNTIFS('Feature Matrix'!$B$2:$B$1000,$A13,'Feature Matrix'!$I$2:$I$1000,E$5) -> 1 | F13: =SUM(B13:E13) -> 25 | G13: =IFERROR(AVERAGEIFS('Feature Matrix'!$G$2:$G$1000,'Feature Matrix'!$B$2:$B$1000,$A13),0) -> 3.4 | H13: =COUNTIFS('Feature Matrix'!$B$2:$B$1000,$A13,'Feature Matrix'!$J$2:$J$1000,"Free") -> 24 | I13: =COUNTIFS('Feature Matrix'!$B$2:$B$1000,$A13,'Feature Matrix'!$J$2:$J$1000,"Plus")+COUNTIFS('Feature Matrix'!$B$2:$B$1000,$A13,'Feature Matrix'!$J$2:$J$1000,"Pack")+COUNTIFS('Feature Matrix'!$B$2:$B$1000,$A13,'Feature Matrix'!$J$2:$J$1000,"Season") -> 1 | J13: =COUNTIFS('Feature Matrix'!$B$2:$B$1000,$A13,'Feature Matrix'!$J$2:$J$1000,"Ad") -> 0
A14: Health, body and death | B14: =COUNTIFS('Feature Matrix'!$B$2:$B$1000,$A14,'Feature Matrix'!$I$2:$I$1000,B$5) -> 2 | C14: =COUNTIFS('Feature Matrix'!$B$2:$B$1000,$A14,'Feature Matrix'!$I$2:$I$1000,C$5) -> 12 | D14: =COUNTIFS('Feature Matrix'!$B$2:$B$1000,$A14,'Feature Matrix'!$I$2:$I$1000,D$5) -> 5 | E14: =COUNTIFS('Feature Matrix'!$B$2:$B$1000,$A14,'Feature Matrix'!$I$2:$I$1000,E$5) -> 0 | F14: =SUM(B14:E14) -> 19 | G14: =IFERROR(AVERAGEIFS('Feature Matrix'!$G$2:$G$1000,'Feature Matrix'!$B$2:$B$1000,$A14),0) -> 3.4736842 | H14: =COUNTIFS('Feature Matrix'!$B$2:$B$1000,$A14,'Feature Matrix'!$J$2:$J$1000,"Free") -> 18 | I14: =COUNTIFS('Feature Matrix'!$B$2:$B$1000,$A14,'Feature Matrix'!$J$2:$J$1000,"Plus")+COUNTIFS('Feature Matrix'!$B$2:$B$1000,$A14,'Feature Matrix'!$J$2:$J$1000,"Pack")+COUNTIFS('Feature Matrix'!$B$2:$B$1000,$A14,'Feature Matrix'!$J$2:$J$1000,"Season") -> 1 | J14: =COUNTIFS('Feature Matrix'!$B$2:$B$1000,$A14,'Feature Matrix'!$J$2:$J$1000,"Ad") -> 0
A15: Countries and world | B15: =COUNTIFS('Feature Matrix'!$B$2:$B$1000,$A15,'Feature Matrix'!$I$2:$I$1000,B$5) -> 0 | C15: =COUNTIFS('Feature Matrix'!$B$2:$B$1000,$A15,'Feature Matrix'!$I$2:$I$1000,C$5) -> 3 | D15: =COUNTIFS('Feature Matrix'!$B$2:$B$1000,$A15,'Feature Matrix'!$I$2:$I$1000,D$5) -> 10 | E15: =COUNTIFS('Feature Matrix'!$B$2:$B$1000,$A15,'Feature Matrix'!$I$2:$I$1000,E$5) -> 2 | F15: =SUM(B15:E15) -> 15 | G15: =IFERROR(AVERAGEIFS('Feature Matrix'!$G$2:$G$1000,'Feature Matrix'!$B$2:$B$1000,$A15),0) -> 3.4 | H15: =COUNTIFS('Feature Matrix'!$B$2:$B$1000,$A15,'Feature Matrix'!$J$2:$J$1000,"Free") -> 14 | I15: =COUNTIFS('Feature Matrix'!$B$2:$B$1000,$A15,'Feature Matrix'!$J$2:$J$1000,"Plus")+COUNTIFS('Feature Matrix'!$B$2:$B$1000,$A15,'Feature Matrix'!$J$2:$J$1000,"Pack")+COUNTIFS('Feature Matrix'!$B$2:$B$1000,$A15,'Feature Matrix'!$J$2:$J$1000,"Season") -> 1 | J15: =COUNTIFS('Feature Matrix'!$B$2:$B$1000,$A15,'Feature Matrix'!$J$2:$J$1000,"Ad") -> 0
A16: Relationships | B16: =COUNTIFS('Feature Matrix'!$B$2:$B$1000,$A16,'Feature Matrix'!$I$2:$I$1000,B$5) -> 0 | C16: =COUNTIFS('Feature Matrix'!$B$2:$B$1000,$A16,'Feature Matrix'!$I$2:$I$1000,C$5) -> 8 | D16: =COUNTIFS('Feature Matrix'!$B$2:$B$1000,$A16,'Feature Matrix'!$I$2:$I$1000,D$5) -> 7 | E16: =COUNTIFS('Feature Matrix'!$B$2:$B$1000,$A16,'Feature Matrix'!$I$2:$I$1000,E$5) -> 0 | F16: =SUM(B16:E16) -> 15 | G16: =IFERROR(AVERAGEIFS('Feature Matrix'!$G$2:$G$1000,'Feature Matrix'!$B$2:$B$1000,$A16),0) -> 3.8 | H16: =COUNTIFS('Feature Matrix'!$B$2:$B$1000,$A16,'Feature Matrix'!$J$2:$J$1000,"Free") -> 15 | I16: =COUNTIFS('Feature Matrix'!$B$2:$B$1000,$A16,'Feature Matrix'!$J$2:$J$1000,"Plus")+COUNTIFS('Feature Matrix'!$B$2:$B$1000,$A16,'Feature Matrix'!$J$2:$J$1000,"Pack")+COUNTIFS('Feature Matrix'!$B$2:$B$1000,$A16,'Feature Matrix'!$J$2:$J$1000,"Season") -> 0 | J16: =COUNTIFS('Feature Matrix'!$B$2:$B$1000,$A16,'Feature Matrix'!$J$2:$J$1000,"Ad") -> 0
A17: Love and marriage | B17: =COUNTIFS('Feature Matrix'!$B$2:$B$1000,$A17,'Feature Matrix'!$I$2:$I$1000,B$5) -> 0 | C17: =COUNTIFS('Feature Matrix'!$B$2:$B$1000,$A17,'Feature Matrix'!$I$2:$I$1000,C$5) -> 10 | D17: =COUNTIFS('Feature Matrix'!$B$2:$B$1000,$A17,'Feature Matrix'!$I$2:$I$1000,D$5) -> 5 | E17: =COUNTIFS('Feature Matrix'!$B$2:$B$1000,$A17,'Feature Matrix'!$I$2:$I$1000,E$5) -> 2 | F17: =SUM(B17:E17) -> 17 | G17: =IFERROR(AVERAGEIFS('Feature Matrix'!$G$2:$G$1000,'Feature Matrix'!$B$2:$B$1000,$A17),0) -> 3.2352941 | H17: =COUNTIFS('Feature Matrix'!$B$2:$B$1000,$A17,'Feature Matrix'!$J$2:$J$1000,"Free") -> 15 | I17: =COUNTIFS('Feature Matrix'!$B$2:$B$1000,$A17,'Feature Matrix'!$J$2:$J$1000,"Plus")+COUNTIFS('Feature Matrix'!$B$2:$B$1000,$A17,'Feature Matrix'!$J$2:$J$1000,"Pack")+COUNTIFS('Feature Matrix'!$B$2:$B$1000,$A17,'Feature Matrix'!$J$2:$J$1000,"Season") -> 2 | J17: =COUNTIFS('Feature Matrix'!$B$2:$B$1000,$A17,'Feature Matrix'!$J$2:$J$1000,"Ad") -> 0
... A29: Settings, accessibility and safety | B29: =COUNTIFS('Feature Matrix'!$B$2:$B$1000,$A29,'Feature Matrix'!$I$2:$I$1000,B$5) -> 0 | C29: =COUNTIFS('Feature Matrix'!$B$2:$B$1000,$A29,'Feature Matrix'!$I$2:$I$1000,C$5) -> 13 | D29: =COUNTIFS('Feature Matrix'!$B$2:$B$1000,$A29,'Feature Matrix'!$I$2:$I$1000,D$5) -> 6 | E29: =COUNTIFS('Feature Matrix'!$B$2:$B$1000,$A29,'Feature Matrix'!$I$2:$I$1000,E$5) -> 0 | F29: =SUM(B29:E29) -> 19 | G29: =IFERROR(AVERAGEIFS('Feature Matrix'!$G$2:$G$1000,'Feature Matrix'!$B$2:$B$1000,$A29),0) -> 3.6315789 | H29: =COUNTIFS('Feature Matrix'!$B$2:$B$1000,$A29,'Feature Matrix'!$J$2:$J$1000,"Free") -> 19 | I29: =COUNTIFS('Feature Matrix'!$B$2:$B$1000,$A29,'Feature Matrix'!$J$2:$J$1000,"Plus")+COUNTIFS('Feature Matrix'!$B$2:$B$1000,$A29,'Feature Matrix'!$J$2:$J$1000,"Pack")+COUNTIFS('Feature Matrix'!$B$2:$B$1000,$A29,'Feature Matrix'!$J$2:$J$1000,"Season") -> 0 | J29: =COUNTIFS('Feature Matrix'!$B$2:$B$1000,$A29,'Feature Matrix'!$J$2:$J$1000,"Ad") -> 0
A30: Total | B30: =SUM(B6:B29) -> 33 | C30: =SUM(C6:C29) -> 226 | D30: =SUM(D6:D29) -> 172 | E30: =SUM(E6:E29) -> 29 | F30: =SUM(F6:F29) -> 460 | G30: =IFERROR(AVERAGE('Feature Matrix'!$G$2:$G$1000),0) -> 3.3347826 | H30: =SUM(H6:H29) -> 415 | I30: =SUM(I6:I29) -> 37 | J30: =SUM(J6:J29) -> 8
A31: Cross-check: matrix row count | F31: =COUNTA('Feature Matrix'!$A$2:$A$1000) -> 460 | G31: =IF(F31=F30,"OK","MISMATCH") -> OK
A33: 2. Features by Status vs BitLife
A34: Status | B34: Count | C34: Share
A35: Parity | B35: =COUNTIFS('Feature Matrix'!$F$2:$F$1000,A35) -> 31 | C35: =IF($B$38=0,0,B35/$B$38) -> 0.067391304
A36: Improved | B36: =COUNTIFS('Feature Matrix'!$F$2:$F$1000,A36) -> 186 | C36: =IF($B$38=0,0,B36/$B$38) -> 0.40434783
A37: New | B37: =COUNTIFS('Feature Matrix'!$F$2:$F$1000,A37) -> 243 | C37: =IF($B$38=0,0,B37/$B$38) -> 0.52826087
A38: Total | B38: =SUM(B35:B37) -> 460 | C38: =SUM(C35:C37) -> 1
A40: 3. Features by Access (x Priority)
A41: Access | B41: Proto | C41: MVP | D41: Launch | E41: LiveOps | F41: Total | G41: Share
A42: Free | B42: =COUNTIFS('Feature Matrix'!$J$2:$J$1000,$A42,'Feature Matrix'!$I$2:$I$1000,B$41) -> 33 | C42: =COUNTIFS('Feature Matrix'!$J$2:$J$1000,$A42,'Feature Matrix'!$I$2:$I$1000,C$41) -> 210 | D42: =COUNTIFS('Feature Matrix'!$J$2:$J$1000,$A42,'Feature Matrix'!$I$2:$I$1000,D$41) -> 156 | E42: =COUNTIFS('Feature Matrix'!$J$2:$J$1000,$A42,'Feature Matrix'!$I$2:$I$1000,E$41) -> 16 | F42: =SUM(B42:E42) -> 415 | G42: =IF($F$47=0,0,F42/$F$47) -> 0.90217391
A43: Plus | B43: =COUNTIFS('Feature Matrix'!$J$2:$J$1000,$A43,'Feature Matrix'!$I$2:$I$1000,B$41) -> 0 | C43: =COUNTIFS('Feature Matrix'!$J$2:$J$1000,$A43,'Feature Matrix'!$I$2:$I$1000,C$41) -> 8 | D43: =COUNTIFS('Feature Matrix'!$J$2:$J$1000,$A43,'Feature Matrix'!$I$2:$I$1000,D$41) -> 5 | E43: =COUNTIFS('Feature Matrix'!$J$2:$J$1000,$A43,'Feature Matrix'!$I$2:$I$1000,E$41) -> 0 | F43: =SUM(B43:E43) -> 13 | G43: =IF($F$47=0,0,F43/$F$47) -> 0.02826087
A44: Pack | B44: =COUNTIFS('Feature Matrix'!$J$2:$J$1000,$A44,'Feature Matrix'!$I$2:$I$1000,B$41) -> 0 | C44: =COUNTIFS('Feature Matrix'!$J$2:$J$1000,$A44,'Feature Matrix'!$I$2:$I$1000,C$41) -> 1 | D44: =COUNTIFS('Feature Matrix'!$J$2:$J$1000,$A44,'Feature Matrix'!$I$2:$I$1000,D$41) -> 5 | E44: =COUNTIFS('Feature Matrix'!$J$2:$J$1000,$A44,'Feature Matrix'!$I$2:$I$1000,E$41) -> 10 | F44: =SUM(B44:E44) -> 16 | G44: =IF($F$47=0,0,F44/$F$47) -> 0.034782609
A45: Season | B45: =COUNTIFS('Feature Matrix'!$J$2:$J$1000,$A45,'Feature Matrix'!$I$2:$I$1000,B$41) -> 0 | C45: =COUNTIFS('Feature Matrix'!$J$2:$J$1000,$A45,'Feature Matrix'!$I$2:$I$1000,C$41) -> 0 | D45: =COUNTIFS('Feature Matrix'!$J$2:$J$1000,$A45,'Feature Matrix'!$I$2:$I$1000,D$41) -> 5 | E45: =COUNTIFS('Feature Matrix'!$J$2:$J$1000,$A45,'Feature Matrix'!$I$2:$I$1000,E$41) -> 3 | F45: =SUM(B45:E45) -> 8 | G45: =IF($F$47=0,0,F45/$F$47) -> 0.017391304
A46: Ad | B46: =COUNTIFS('Feature Matrix'!$J$2:$J$1000,$A46,'Feature Matrix'!$I$2:$I$1000,B$41) -> 0 | C46: =COUNTIFS('Feature Matrix'!$J$2:$J$1000,$A46,'Feature Matrix'!$I$2:$I$1000,C$41) -> 7 | D46: =COUNTIFS('Feature Matrix'!$J$2:$J$1000,$A46,'Feature Matrix'!$I$2:$I$1000,D$41) -> 1 | E46: =COUNTIFS('Feature Matrix'!$J$2:$J$1000,$A46,'Feature Matrix'!$I$2:$I$1000,E$41) -> 0 | F46: =SUM(B46:E46) -> 8 | G46: =IF($F$47=0,0,F46/$F$47) -> 0.017391304
A47: Total | B47: =SUM(B42:B46) -> 33 | C47: =SUM(C42:C46) -> 226 | D47: =SUM(D42:D46) -> 172 | E47: =SUM(E42:E46) -> 29 | F47: =SUM(F42:F46) -> 460 | G47: =SUM(G42:G46) -> 1
A49: 4. Fair-forever checks (pillar 3: all careers and core systems free)
A50: Check | B50: Count | C50: Result | D50: How it is calculated
A51: Career / core-system rows with Access = Plus or Pack | B51: =COUNTIFS('Feature Matrix'!$M$2:$M$1000,"Yes",'Feature Matrix'!$J$2:$J$1000,"Plus")+COUNTIFS('Feature Matrix'!$M$2:$M$1000,"Yes",'Feature Matrix'!$J$2:$J$1000,"Pack") -> 0 | C51: =IF(B51=0,"PASS","FAIL") -> PASS | D51: Rows flagged 'Career / core system? = Yes' whose Access is Plus or Pack. Must be 0.
A52: Career / core-system rows with any paid or ad Access (Plus, Pack, Season, Ad) | B52: =COUNTIFS('Feature Matrix'!$M$2:$M$1000,"Yes",'Feature Matrix'!$J$2:$J$1000,"<>Free") -> 0 | C52: =IF(B52=0,"PASS","FAIL") -> PASS | D52: Stricter variant: every flagged row must be Free. Must be 0.
A53: Rows named '... career' in Careers and jobs that are not Free | B53: =COUNTIFS('Feature Matrix'!$B$2:$B$1000,"Careers and jobs",'Feature Matrix'!$C$2:$C$1000,"*career*",'Feature Matrix'!$J$2:$J$1000,"<>Free") -> 0 | C53: =IF(B53=0,"PASS","FAIL") -> PASS | D53: Independent of the flag: every individual career row must be Free. Must be 0.
A54: Rows named '... career' in Careers and jobs (count covered) | B54: =COUNTIFS('Feature Matrix'!$B$2:$B$1000,"Careers and jobs",'Feature Matrix'!$C$2:$C$1000,"*career*") -> 32 | C54: Info | D54: Informational: how many career rows the check above covers.
A55: Overall fair-forever check | C55: =IF(AND(C51="PASS",C52="PASS",C53="PASS"),"PASS","FAIL") -> PASS

Sheet Store Catalogue
A1: Store Catalogue (from 06 Monetization and Economy, Section 2 and Section 4)
A2: Prices are US-dollar store tiers (estimates; regional pricing via store tiers). Blue = hardcoded input from note 06; black = formula.
A4: ID | B4: Product | C4: Price USD | D4: Contents | E4: Type | F4: Platform | G4: Access tag | H4: Notes
A5: P1 | B5: Relivable Plus | C5: 9.99 | D5: Removes all ads and auto-grants rewarded-ad perks. Up to 8 generations per dynasty (free tier: Generation 4, founder + 3 heirs; unlimited number of dynasties). Destiny Mode editor tools. Unlimited Rewind (free: 1 per life + 1 per day via rewarded ad). Extra save slots. Plus badge on the recap card. | E5: Non-consumable | F5: iOS, Android, web | G5: Plus | H5: Save slots: 10 (free 3).
A6: P2 | B6: No Ads | C6: 2.99 | D6: Removes all ads and auto-grants ad perks. Nothing else. | E6: Non-consumable | F6: iOS, Android, web | G6: Plus | H6: Entry-level supporter price; matches BitLife Remove Ads $2.99.
A7: P3 | B7: Plus Upgrade (No-Ads owners only) | C7: 6.99 | D7: Everything else in Plus. Total paid never exceeds Plus (see check below). | E7: Non-consumable | F7: iOS, Android, web | G7: Plus
A8: P4a | B8: Story Pack (small) | C8: 2.99 | D8: About 60 storylets: new storylines, characters, scenario starts and Milestones. Never a career, a system or a stat edge. | E8: Non-consumable | F8: iOS, Android, web | G8: Pack | H8: Examples: Spotlight, Night Shift, Old Money, Frontier 1850, The Uncanny.
A9: P4b | B9: Story Pack (large) | C9: 3.99 | D9: About 120 storylets + 1 new scenario start. Never a career, a system or a stat edge. | E9: Non-consumable | F9: iOS, Android, web | G9: Pack | H9: Released about every 2 months.
A10: P5 | B10: Season Pass | C10: 4.99 | D10: Premium track: about 30 cosmetic rewards + 2 bonus story chapters. Free track for everyone: about 20 rewards + main season storyline. Items kept forever. | E10: Non-consumable per season (non-renewing) | F10: iOS, Android, web | G10: Season | H10: Season length: about 13 weeks.
A11: P6 | B11: Welcome Pack | C11: 1.99 | D11: Avatar outfit set (5), 3 recap card themes, family crest starter. Cosmetic only. Once per account. | E11: Non-consumable | F11: iOS, Android | G11: Pack | H11: Offered after the first life ends (A/B test vs age 18 in life 1).
A12: P7a | B12: Cosmetic set (small) | C12: 0.99 | D12: One themed set (outfits, décor or recap theme). | E12: Non-consumable | F12: iOS, Android, web | G12: Pack | H12: Cosmetic sets range $0.99-1.99.
A13: P7b | B13: Cosmetic set (large) | C13: 1.99 | D13: One themed set (outfits, décor or recap theme). | E13: Non-consumable | F13: iOS, Android, web | G13: Pack | H13: Cosmetic sets range $0.99-1.99.
A14: P8 | B14: Founder's Bundle (60-day launch window) | C14: 14.99 | D14: Plus + 2 large Story Packs + exclusive founder crest. | E14: Non-consumable | F14: iOS, Android, web | G14: Pack | H14: Component value computed below.
A15: P9 | B15: Complete Collection (evergreen) | C15: 24.99 | D15: Plus + all currently released Story Packs (value shown in store). | E15: Non-consumable bundle | F15: iOS, Android, web | G15: Pack | H15: Value grows with each released pack.
A16: A1 | B16: Rewarded ad: Extra Rewind | C16: 0 | D16: +1 Rewind (1 per day). | E16: Rewarded ad (opt-in) | F16: iOS, Android | G16: Ad | H16: Resolved decision: 1 free Rewind per life + 1 per day via ad (note 06 placement table said 2 per life).
A17: A2 | B17: Rewarded ad: Second opinion | C17: 0 | D17: Reveal odds band and hidden factors of one risky choice. | E17: Rewarded ad (opt-in) | F17: iOS, Android | G17: Ad | H17: Cap 3/day. Information, not outcome manipulation.
A18: A3 | B18: Rewarded ad: Lucky break | C18: 0 | D18: Retry one failed non-death minor action. | E18: Rewarded ad (opt-in) | F18: iOS, Android | G18: Ad | H18: Cap 2/day. Never undoes a death.
A19: A4 | B19: Rewarded ad: Sparks bonus | C19: 0 | D19: +50 Sparks (earn-only soft currency). | E19: Rewarded ad (opt-in) | F19: iOS, Android | G19: Ad | H19: Cap 3/day.
... A21: A6 | B21: Rewarded ad: Daily goal reroll | C21: 0 | D21: Replace one daily goal. | E21: Rewarded ad (opt-in) | F21: iOS, Android | G21: Ad | H21: Cap 1/day.
A22: X | B22: Not sold | D22: Careers, life stages, dark mode, accessibility, per-use Rewind, event rerolls, stat boosts, premium currency, random rewards, subscriptions (at launch). | E22: - | F22: - | G22: - | H22: Sparks are earn-only and never sold. All ads: rewarded only, max 4 per session, 8 per day, 90 s cooldown.
A24: Price checks (formulas)
A25: Check | C25: Value USD | D25: Explanation
A26: No Ads + Plus Upgrade | C26: =C6+C7 -> 9.98 | D26: Total paid by a No-Ads owner who upgrades
A27: Plus price | C27: =C5 -> 9.99 | D27: Reference
A28: Upgrade path never costs more than Plus | C28: =IF(C26<=C27,"PASS","FAIL") -> PASS | D28: Rule from note 06 P3
A29: Founder's Bundle component value | C29: =C5+2*C9 -> 17.97 | D29: Plus + 2 large Story Packs (note 06: $17.97)
A30: Founder's Bundle saving | C30: =C29-C14 -> 2.98 | D30: Component value minus bundle price
A31: Founder's Bundle saving % | C31: =IF(C29=0,0,C30/C29) -> 0.16583194 | D31: Share of component value

Sheet Budget
A1: Budget per phase (from 11 Roadmap Team and Budget, Section 4) - USD, excl. user acquisition
A2: Estimates, not quotes. Blue = hardcoded line items from note 11; black = SUM formulas. Low = hybrid/LatAm, High = Eastern Europe, US = US-team reference.
A4: Phase | B4: Line item | C4: Low (USD) | D4: High (USD) | E4: US ref (USD) | F4: US ref upper (USD) | G4: Notes
A5: Phase 2 Prototype (8 wk, ~3.0 FTE, ~890 h) | B5: Labour (~890 h) | C5: 22000 | D5: 53000 | E5: 98000 | F5: 98000 | G5: Low hybrid ~$25/h; High EE $60/h; US $110/h
A6: Phase 2 Prototype (8 wk, ~3.0 FTE, ~890 h) | B6: Playtests (moderated + unmoderated) | C6: 1500 | D6: 3000 | E6: 3000 | F6: 3000
A7: Phase 2 Prototype (8 wk, ~3.0 FTE, ~890 h) | B7: Tools/services (2 months) | C7: 500 | D7: 1000 | E7: 1000 | F7: 1000
A8: Phase 2 Prototype (8 wk, ~3.0 FTE, ~890 h) | B8: Test devices (3 low/mid Android + 1 iPhone) | C8: 1000 | D8: 2000 | E8: 2000 | F8: 2000
A9: Phase 2 Prototype (8 wk, ~3.0 FTE, ~890 h) | B9: Trademark/name search (preliminary) | C9: 0 | D9: 1000 | E9: 1000 | F9: 1000 | G9: Low case: paid by client
A10: Phase 2 Prototype (8 wk, ~3.0 FTE, ~890 h) | B10: Phase total | C10: =SUM(C5:C9) -> 25000 | D10: =SUM(D5:D9) -> 60000 | E10: =SUM(E5:E9) -> 105000 | F10: =SUM(F5:F9) -> 105000
A11: Phase 3 MVP + soft-launch start (~5 mo, ~4.4 FTE, ~3,520 h) | B11: Labour (3,520 h) | C11: 60000 | D11: 210000 | E11: 385000 | F11: 385000 | G11: Mid (India $30/h) $105K and LatAm ($50/h) $175K scenarios in note 11 not shown
A12: Phase 3 MVP + soft-launch start (~5 mo, ~4.4 FTE, ~3,520 h) | B12: Legal/privacy counsel (tranche 1) | C12: 8000 | D12: 20000 | E12: 20000 | F12: 20000 | G12: Privacy policy, ToS, DPIA, COPPA retention policy
A13: Phase 3 MVP + soft-launch start (~5 mo, ~4.4 FTE, ~3,520 h) | B13: Sensitivity review (external reader) | C13: 2000 | D13: 5000 | E13: 5000 | F13: 5000
A14: Phase 3 MVP + soft-launch start (~5 mo, ~4.4 FTE, ~3,520 h) | B14: Art outsourcing (event cards, avatar layers) | C14: 5000 | D14: 15000 | E14: 15000 | F14: 15000
A15: Phase 3 MVP + soft-launch start (~5 mo, ~4.4 FTE, ~3,520 h) | B15: Tools/services (5 months) | C15: 3000 | D15: 6000 | E15: 6000 | F15: 6000
A16: Phase 3 MVP + soft-launch start (~5 mo, ~4.4 FTE, ~3,520 h) | B16: Playtests + devices | C16: 4000 | D16: 8000 | E16: 8000 | F16: 8000
A17: Phase 3 MVP + soft-launch start (~5 mo, ~4.4 FTE, ~3,520 h) | B17: Phase total | C17: =SUM(C11:C16) -> 82000 | D17: =SUM(D11:D16) -> 264000 | E17: =SUM(E11:E16) -> 439000 | F17: =SUM(F11:F16) -> 439000
A18: Phase 4 Global launch (~4 mo, ~9-10.5 FTE) | B18: Labour | C18: 288000 | D18: 451000 | E18: 634000 | F18: 827000 | G18: Low LatAm $50/h x 5,760 h; High EE $60/h x 7,520 h; US $634K-827K
A19: Phase 4 Global launch (~4 mo, ~9-10.5 FTE) | B19: Localisation (~1.2M words at $0.06-0.12/word) | C19: 72000 | D19: 144000 | E19: 144000 | F19: 144000 | G19: Per-word rates NOT researched (assumption)
A20: Phase 4 Global launch (~4 mo, ~9-10.5 FTE) | B20: LQA + localised store assets | C20: 8000 | D20: 15000 | E20: 15000 | F20: 15000
A21: Phase 4 Global launch (~4 mo, ~9-10.5 FTE) | B21: External accessibility audit (WCAG 2.2 AA / EN 301 549) | C21: 8000 | D21: 20000 | E21: 25000 | F21: 25000
A22: Phase 4 Global launch (~4 mo, ~9-10.5 FTE) | B22: Legal tranche 2 (LGPD, EU consumer, web shop, rating) | C22: 7000 | D22: 30000 | E22: 30000 | F22: 30000
A23: Phase 4 Global launch (~4 mo, ~9-10.5 FTE) | B23: Trailer + key art + store creative | C23: 5000 | D23: 15000 | E23: 20000 | F23: 20000
A24: Phase 4 Global launch (~4 mo, ~9-10.5 FTE) | B24: Tools/services (4 months) | C24: 4000 | D24: 8000 | E24: 8000 | F24: 8000
A25: Phase 4 Global launch (~4 mo, ~9-10.5 FTE) | B25: QA device lab / Test Lab overage | C25: 3000 | D25: 8000 | E25: 8000 | F25: 8000
A26: Phase 4 Global launch (~4 mo, ~9-10.5 FTE) | B26: Contingency (~5%) | C26: 3000 | D26: 10000 | E26: 0 | F26: 0 | G26: No contingency line in the US reference
A27: Phase 4 Global launch (~4 mo, ~9-10.5 FTE) | B27: Phase total | C27: =SUM(C18:C26) -> 398000 | D27: =SUM(D18:D26) -> 701000 | E27: =SUM(E18:E26) -> 884000 | F27: =SUM(F18:F26) -> 1077000
A28: Cumulative to global launch | B28: Phases 2 + 3 + 4 | C28: =C10+C17+C27 -> 505000 | D28: =D10+D17+D27 -> 1025000 | E28: =E10+E17+E27 -> 1428000 | F28: =F10+F17+F27 -> 1621000 | G28: Note 11: ~$505K / ~$1.03M / ~$1.43M-1.62M. Brief: ~$0.5-1.1M (EE/LatAm), $1.2-2M (US).
A30: Phase 5 LiveOps run rate (per month)
A31: Phase | B31: Line item | C31: Low (LatAm, 6 FTE) | D31: High (EE, 8 FTE) | E31: US ref (7 FTE) | G31: Notes
A32: Phase 5 LiveOps (monthly) | B32: Labour (960-1,280 h) | C32: 48000 | D32: 77000 | E32: 123000
A33: Phase 5 LiveOps (monthly) | B33: Services (Firebase, Crowdin, MMP, CI, ASO tool) | C33: 1000 | D33: 3000 | E33: 3000
A34: Phase 5 LiveOps (monthly) | B34: Localisation of new content (~20-30K words/mo x 4) | C34: 5000 | D34: 10000 | E34: 10000
A35: Phase 5 LiveOps (monthly) | B35: Monthly total (excl. UA, RevenueCat 1%, cloud AI) | C35: =SUM(C32:C34) -> 54000 | D35: =SUM(D32:D34) -> 90000 | E35: =SUM(E32:E34) -> 136000
A36: Phase 5 LiveOps | B36: Annualised (x12) | C36: =C35*12 -> 648000 | D36: =D35*12 -> 1080000 | E36: =E35*12 -> 1632000
A38: Excluded: GTM/UA ~$46-103K soft launch and ~$225-715K first 90 days after launch (note 10, Section 10). RevenueCat 1% above $2.5K monthly tracked revenue; cloud AI ~$0.27 per opted-in user per month.

Sheet Roadmap
A1: Roadmap, milestones and team (from 11 Roadmap Team and Budget, Sections 1-3)
A2: Target dates are gated (see 12 Risks and KPIs, Section 3). A missed gate moves everything after it; fallback launch window Jan 2028.
A4: Phase | B4: Start | C4: End | D4: Duration (weeks) | E4: Team (avg FTE) | F4: Gate / milestone | G4: Gate date | H4: Key deliverables | I4: Exit criteria
A5: 1 Planning | B5: 46296 | C5: 46325 | D5: =ROUND((C5-B5)/7,1) -> 4.1 | E5: Founder | F5: Gate 1: client sign-off | G5: 46332 | H5: Research vault, app breakdowns, UX, monetisation, tech, compliance, GTM, budget, risks; pitch deck outline | I5: Scope, budget and stack approved; name clearance started
A6: 2 Prototype | B6: 46335 | C6: 46395 | D6: =ROUND((C6-B6)/7,1) -> 8.6 | E6: 3.0 | F6: Gate 2: prototype | G6: 46395 | H6: Storylet engine + validator + sim bot v1; redesigned hub, command bar, event cards; birth-to-30 slice; 150 events with 15+ callback arcs; screen-reader spike; Flutter-vs-Unity decision | I6: Fun/clarity scores at target; tick <= 50 ms; screen-reader pass; >= 6 events/writer-day
A7: 3 MVP + Soft launch | B7: 46398 | C7: 46552 | D7: =ROUND((C7-B7)/7,1) -> 22 | E7: 4.4 | F7: Gate 3: MVP to soft launch | G7: 46521 | H7: Full life cycle, core careers, 1,500+ events, cloud save, RevenueCat (Plus + 1 pack), capped rewarded ads, analytics, compliance build, Life Recap v1, weekly challenge v1; soft launch W1 Philippines from 17 May 2027 | I7: Crash-free >= 99.5% in beta; FTUE >= 85%; Phase 3 compliance items done
A8: 4 Global launch | B8: 46552 | C8: 46672 | D8: =ROUND((C8-B8)/7,1) -> 17.1 | E8: 9.0-10.5 | F8: Gate 4: go/no-go (30 Aug 2027); Global launch | G8: 46672 | H8: Soft launch W2/W3 (IE, NL, CA); parity + 'better' features; 3,000+ events; 5 languages; Season Pass v1; optional US web shop; external a11y audit; localised ASO | I8: Soft-launch KPI gates met; audit pass; rating confirmed
A9: 5 LiveOps | B9: 46672 | C9: 46934 | D9: =ROUND((C9-B9)/7,1) -> 37.4 | E9: 6-8 | F9: Gate 5: launch + 90 days (Jan 2028); quarterly reviews | G9: 46762 | H9: Weekly challenges (52/yr), monthly events, quarterly Story Pack, seasons, era mode, async social, Creator Mode beta, optional AI NPC chat | I9: Ongoing; end date is the last task in the note 11 Gantt chart (30 Jun 2028). Retention and monetisation KPIs; content cadence held 3 months
A11: Schedule check
A12: Months from Phase 2 start to global launch | D12: =ROUND((G8-B6)/30.44,1) -> 11.1
A13: Inside brief window of 9-14 months? | D13: =IF(AND(D12>=9,D12<=14),"YES","NO") -> YES
A15: Gantt tasks (note 11, Section 1)
A16: Phase | B16: Task | C16: Start | D16: End | E16: Days | F16: Critical path? | G16: Type
A17: 1 Planning | B17: Research + vault + pitch | C17: 46296 | D17: 46325 | E17: =D17-C17 -> 29 | G17: Task
A18: 1 Planning | B18: Client sign-off (Gate 1) | C18: 46332 | D18: 46332 | E18: =D18-C18 -> 0 | G18: Milestone
A19: 2 Prototype | B19: Tech spikes (a11y, engine, IAP) | C19: 46335 | D19: 46353 | E19: =D19-C19 -> 18 | G19: Task
A20: 2 Prototype | B20: Vertical slice birth to 30 | C20: 46349 | D20: 46388 | E20: =D20-C20 -> 39 | G20: Task
A21: 2 Prototype | B21: 150 events + sim bot v1 | C21: 46342 | D21: 46388 | E21: =D21-C21 -> 46 | G21: Task
A22: 2 Prototype | B22: Playtests + Gate 2 | C22: 46384 | D22: 46395 | E22: =D22-C22 -> 11 | G22: Task
A23: 2 Prototype | B23: Gate 2 Prototype | C23: 46395 | D23: 46395 | E23: =D23-C23 -> 0 | G23: Milestone
A24: 3 MVP + Soft launch | B24: Full life cycle + core careers | C24: 46398 | D24: 46493 | E24: =D24-C24 -> 95 | G24: Task
A25: 3 MVP + Soft launch | B25: Monetization + analytics + saves | C25: 46433 | D25: 46507 | E25: =D25-C25 -> 74 | G25: Task
A26: 3 MVP + Soft launch | B26: Content to 1,500 events | C26: 46398 | D26: 46521 | E26: =D26-C26 -> 123 | F26: Yes | G26: Task
A27: 3 MVP + Soft launch | B27: Compliance build (age, privacy) | C27: 46447 | D27: 46514 | E27: =D27-C27 -> 67 | G27: Task
A28: 3 MVP + Soft launch | B28: Beta (Discord, TestFlight, Play) | C28: 46496 | D28: 46521 | E28: =D28-C28 -> 25 | G28: Task
A29: 3 MVP + Soft launch | B29: Gate 3 MVP | C29: 46521 | D29: 46521 | E29: =D29-C29 -> 0 | G29: Milestone
A30: 3 MVP + Soft launch | B30: Soft launch W1 Philippines | C30: 46524 | D30: 46552 | E30: =D30-C30 -> 28 | G30: Task
A31: 4 Global launch | B31: Soft launch W2/W3 (IE, NL, CA) | C31: 46552 | D31: 46629 | E31: =D31-C31 -> 77 | G31: Task
A32: 4 Global launch | B32: Parity + better features | C32: 46552 | D32: 46654 | E32: =D32-C32 -> 102 | G32: Task
A33: 4 Global launch | B33: Content to 3,000+ events | C33: 46524 | D33: 46647 | E33: =D33-C33 -> 123 | F33: Yes | G33: Task
A34: 4 Global launch | B34: Localisation ES, PT-BR, DE, FR | C34: 46573 | D34: 46660 | E34: =D34-C34 -> 87 | G34: Task
A35: 4 Global launch | B35: Accessibility audit + fixes | C35: 46615 | D35: 46654 | E35: =D35-C35 -> 39 | G35: Task
A36: 4 Global launch | B36: Gate 4 Go/No-go | C36: 46629 | D36: 46629 | E36: =D36-C36 -> 0 | G36: Milestone
A37: 4 Global launch | B37: Global launch | C37: 46672 | D37: 46672 | E37: =D37-C37 -> 0 | F37: Yes | G37: Milestone
A38: 5 LiveOps | B38: Weekly challenges + seasons | C38: 46672 | D38: 46934 | E38: =D38-C38 -> 262 | G38: Task
A39: 5 LiveOps | B39: Story Packs (quarterly) | C39: 46722 | D39: 46934 | E39: =D39-C39 -> 212 | G39: Task
A40: 5 LiveOps | B40: Async social | C40: 46762 | D40: 46871 | E40: =D40-C40 -> 109 | G40: Task
A41: 5 LiveOps | B41: Creator Mode (UGC) beta | C41: 46813 | D41: 46934 | E41: =D41-C41 -> 121 | G41: Task
A43: Team composition, FTE per phase (note 11, Section 3)
A44: Role | B44: P2 Prototype | C44: P3 MVP | D44: P4 Launch | E44: P5 LiveOps (low) | F44: P5 LiveOps (high) | G44: Notes
...

Sheet KPIs
A1: KPIs (from 12 Risks and KPIs, Section 2)
A2: Targets are hypotheses calibrated against public benchmarks, to be re-based on prototype and soft-launch data. They are not forecasts.
A4: ID | B4: Category | C4: KPI | D4: Definition | E4: Target | F4: Benchmark | G4: Source
A5: KPI-NS-01 | B5: North Star | C5: Weekly Story Players (WSP) | D5: Unique users who age a character >= 10 in-game years in a calendar week | E5: WSP/MAU >= 45% (launch + 90 days); absolute target set after soft launch | F5: None (Relivable-specific) | G5: 12 Risks and KPIs, 2.1
A6: KPI-NS-02 | B6: North Star | C6: Callback-experienced rate | D6: % of completed lives in which >= 3 memory callbacks fired | E6: >= 80% | F6: None (measures pillar 1) | G6: 12 Risks and KPIs, 2.1
A7: KPI-AQ-01 | B7: Acquisition | C7: Store page conversion | D7: Store page views that become installs | E7: >= 30% iOS / >= 25% Play | F7: Estimate; first 3 screenshots drive it (AppTweak) | G7: 12 Risks and KPIs, 2.2
A8: KPI-AQ-02 | B8: Acquisition | C8: Organic share of installs | D8: Organic installs / all installs, launch + 90 days | E8: >= 50% | F8: Organic-first strategy | G8: 12 Risks and KPIs, 2.2
A9: KPI-AQ-03 | B9: Acquisition | C9: Blended CPI | D9: Paid UA spend / paid installs | E9: <= $2.50 US iOS / <= $1.20 Android | F9: NA casual about $3 / $2 (Segwise) | G9: 12 Risks and KPIs, 2.2
A10: KPI-AQ-04 | B10: Acquisition | C10: IPM (top creative) | D10: Installs per 1,000 ad impressions for the best creative | E10: >= 2x account median; UGC creatives tested weekly | F10: UGC +152% IPM (Liftoff 2025) | G10: 12 Risks and KPIs, 2.2
A11: KPI-AQ-05 | B11: Acquisition | C11: Pre-registrations by launch | D11: Store pre-registrations before global launch | E11: 50-150K (low confidence) | F11: No conversion data found (gap) | G11: 12 Risks and KPIs, 2.2
A12: KPI-AQ-06 | B12: Acquisition | C12: Recap share rate | D12: Share of finished lives whose Life Recap is shared | E12: >= 8% | F12: Spotify Wrapped precedent (RouteNote) | G12: 12 Risks and KPIs, 2.2
A13: KPI-AQ-07 | B13: Acquisition | C13: Seed open to install | D13: Share of shared-seed link opens that become installs | E13: >= 15% | F13: Spotify Wrapped precedent (RouteNote) | G13: 12 Risks and KPIs, 2.2
A14: KPI-AQ-08 | B14: Acquisition | C14: K-factor | D14: New users generated per existing user through sharing | E14: 0.15-0.30 | F14: Spotify Wrapped precedent (RouteNote) | G14: 12 Risks and KPIs, 2.2
A15: KPI-EN-01 | B15: Engagement | C15: Sessions per DAU | D15: Sessions / daily active users | E15: >= 2.5 | F15: Estimate | G15: 12 Risks and KPIs, 2.3
... A49: KPI-QT-10 | B49: Quality and trust | C49: Support first response | D49: Time to first support response | E49: < 24 h | F49: - | G49: 12 Risks and KPIs, 2.6
